Workbook

Sheet Inputs
B2: Inputs | J2: Legend
J3: User input, hard-coded default value | K3: Value
C4: General Inputs | J4: User input, calculated default value (user can over ride | K4: Value
C5: Analysis Period (Project Life) | D5: 25 | E5: years (40 max) | J5: User input, drop down selection | K5: Value
C6: Discount Rate | D6: 0.07 | E6: % per annum | J6: Input not applicable (user can over ride) | K6: Value
C7: Inflation Rate | D7: 0.02 | E7: % per annum | J7: Read-only output | K7: Value
C8: Desired Confidence that Reserve Covers Cost | D8: 0.92
C9: Working Hours/year | D9: 2080
C11: Plant Inputs
C12: Plant Name | D12: Ground Mount Fixed Tilt
C13: Location | D13: Denver, CO
C14: Plant Size (kWp DC) | D14: 10000
C15: Plant Size (Wp DC) | D15: =D14*1000 -> 10000000
C16: Energy Yield Year 1 (kWh/kWp/year) | D16: 1400
C17: Plant Installed Cost | D17: 3000000
C18: Module Efficiency | D18: 0.16
C19: Module Power (W STC) | D19: 305
C20: Array Area (m2) | D20: =D15/1000/D18 -> 62500
C21: Number of Modules | D21: =ROUNDUP(D15/D19,0) -> 32787
C22: Module Type/ Degradation | D22: Mono-crystal silicon: 0.36%/year
C23: Degradation Rate per year | D23: =VLOOKUP(D22,Lists!D2:E8,2,FALSE) -> 0.0036
C24: Modules per String | D24: 14
C25: Number of Strings | D25: =D15/D19/D24 -> 2341.9204
C26: Strings per Combiner Box | D26: 15
C27: Number of Combiner Boxes | D27: =IF(D26=0,0,ROUNDUP(D25/D26,0)) -> 157
C28: Combiner boxes per DC disconnect | D28: 1
C29: Number of DC Disconnects | D29: =IF(D27=0,1,IF(D28=0,1,ROUNDUP(D27/D28,0))) -> 157
C30: Inverter Type | D30: Central Inverter
C31: Inverter Replacement Cost/ Wp | D31: =VLOOKUP($D$30,Lists!M2:N5,2,FALSE) -> 0.19
C32: Number of Inverters | D32: 10
C33: Inverter Capacity (kWp) | D33: 1000
C34: Number of Transformers | D34: 10
C36: Inverter Warranty (years) | D36: 10
C37: PV Module Product Warranty (years) | D37: 20
C38: Other equipment (EPC) Warranty (years) | D38: 1
C39: Purchased monitoring contract (years) | D39: 0 | E39: Enter '0' if not applicable
C41: Market Sector | D41: Utility (1 MW)
C42: Mounting Location | D42: Ground Mount
C43: Roof Slope | D43: Sloped, 4:12
C44: Roof Type | D44: Composite Shingle
...

Sheet Report
A1: Plant Name | B1: =Inputs!D12 -> Ground Mount Fixed Tilt | D1: Lifetime NPV by Service Provider | I1: Lifetime NPV by O&M Category | N1: Year | O1: ='Detailed Measures'!AA2 -> 1 | P1: ='Detailed Measures'!AB2 -> 2 | Q1: ='Detailed Measures'!AC2 -> 3 | R1: ='Detailed Measures'!AD2 -> 4 | S1: ='Detailed Measures'!AE2 -> 5 | T1: ='Detailed Measures'!AF2 -> 6 | U1: ='Detailed Measures'!AG2 -> 7 | V1: ='Detailed Measures'!AH2 -> 8 | ... BB1: ='Detailed Measures'!BN2 -> 40
D2: Service Provider | E2: Avg. Cost/Yr | F2: NPV (Life) | G2: % of Total | I2: O&M Category | J2: Avg. Cost/Yr | K2: NPV (Life) | L2: % of Total | N2: Annual Cash Flow | O2: ='Detailed Measures'!AA137 -> 60724.044 | P2: ='Detailed Measures'!AB137 -> 92998.134 | Q2: ='Detailed Measures'!AC137 -> 93544.663 | R2: ='Detailed Measures'!AD137 -> 96139.882 | S2: ='Detailed Measures'!AE137 -> 126946.47 | T2: ='Detailed Measures'!AF137 -> 100090.6 | U2: ='Detailed Measures'!AG137 -> 101371.86 | V2: ='Detailed Measures'!AH137 -> 104857.33 | ... BB2: ='Detailed Measures'!BN137 -> 0
A3: Results | D3: Administrator | E3: =SUMIF('Detailed Measures'!$J$3:$J$136,D3,'Detailed Measures'!$X$3:$X$136) -> 7717.4876 | F3: =SUMIF('Detailed Measures'!$J$3:$J$136,D3,'Detailed Measures'!$Y$3:$Y$136) -> 88635.448 | G3: =F3/$F$18 -> 0.041804805 | I3: =Lists!C3 -> AC Wiring | J3: =SUMIF('Detailed Measures'!$D$3:$D$136,I3,'Detailed Measures'!$X$3:$X$136) -> 2054.8769 | K3: =SUMIF('Detailed Measures'!$D$3:$D$136,I3,'Detailed Measures'!$Y$3:$Y$136) -> 22299.464 | L3: =K3/$K$18 -> 0.010519486 | N3: Reserve Account Amount | O3: ='Detailed Measures'!BQ137 -> 61847.328 | P3: ='Detailed Measures'!BR137 -> 155324.23 | Q3: ='Detailed Measures'!BS137 -> 150035.1 | R3: ='Detailed Measures'!BT137 -> 146930.98 | S3: ='Detailed Measures'!BU137 -> 172198.29 | T3: ='Detailed Measures'!BV137 -> 139985.54 | U3: ='Detailed Measures'!BW137 -> 136113.01 | V3: ='Detailed Measures'!BX137 -> 135394.43 | ... BB3: ='Detailed Measures'!DD137 -> 0
A4: Annualized O&M Costs ($/year) | B4: =B7/(((1+Inputs!D7)/(Inputs!D6-Inputs!D7)*(1-((1+Inputs!D7)/(1+Inputs!D6))^Inputs!D5))) -> 148960.15 | D4: Cleaner | E4: =SUMIF('Detailed Measures'!$J$3:$J$136,D4,'Detailed Measures'!$X$3:$X$136) -> 23710.307 | F4: =SUMIF('Detailed Measures'!$J$3:$J$136,D4,'Detailed Measures'!$Y$3:$Y$136) -> 272344.67 | G4: =F4/$F$18 -> 0.12845104 | I4: =Lists!C4 -> DC Wiring | J4: =SUMIF('Detailed Measures'!$D$3:$D$136,I4,'Detailed Measures'!$X$3:$X$136) -> 32954.81 | K4: =SUMIF('Detailed Measures'!$D$3:$D$136,I4,'Detailed Measures'!$Y$3:$Y$136) -> 416042.67 | L4: =K4/$K$18 -> 0.19626278
A5: Annualized Unit O&M Costs ($/kW/year) | B5: =B4/(Inputs!D15/1000) -> 14.896015 | D5: Inverter specialist | E5: =SUMIF('Detailed Measures'!$J$3:$J$136,D5,'Detailed Measures'!$X$3:$X$136) -> 29782.305 | F5: =SUMIF('Detailed Measures'!$J$3:$J$136,D5,'Detailed Measures'!$Y$3:$Y$136) -> 268749.26 | G5: =F5/$F$18 -> 0.12675527 | I5: =Lists!C5 -> Asset Management | J5: =SUMIF('Detailed Measures'!$D$3:$D$136,I5,'Detailed Measures'!$X$3:$X$136) -> 4548.8299 | K5: =SUMIF('Detailed Measures'!$D$3:$D$136,I5,'Detailed Measures'!$Y$3:$Y$136) -> 52249.412 | L5: =K5/$K$18 -> 0.024647988
A6: Maximum Reserve Account | B6: =MAX('Detailed Measures'!BQ137:DD137) -> 1519994.1 | D6: Inspector | E6: =SUMIF('Detailed Measures'!$J$3:$J$136,D6,'Detailed Measures'!$X$3:$X$136) -> 25548.641 | F6: =SUMIF('Detailed Measures'!$J$3:$J$136,D6,'Detailed Measures'!$Y$3:$Y$136) -> 287353.09 | G6: =F6/$F$18 -> 0.13552974 | I6: =Lists!C6 -> Documents | J6: =SUMIF('Detailed Measures'!$D$3:$D$136,I6,'Detailed Measures'!$X$3:$X$136) -> 3115.3948 | K6: =SUMIF('Detailed Measures'!$D$3:$D$136,I6,'Detailed Measures'!$Y$3:$Y$136) -> 35784.488 | L6: =K6/$K$18 -> 0.016880872
A7: Net Present Value O&M Costs (project life) | B7: ='Detailed Measures'!Y137 -> 2120221.6 | D7: Journeyman electrician | E7: =SUMIF('Detailed Measures'!$J$3:$J$136,D7,'Detailed Measures'!$X$3:$X$136) -> 11209.753 | F7: =SUMIF('Detailed Measures'!$J$3:$J$136,D7,'Detailed Measures'!$Y$3:$Y$136) -> 577876.97 | G7: =F7/$F$18 -> 0.27255499 | I7: =Lists!C7 -> Electrical | J7: =SUMIF('Detailed Measures'!$D$3:$D$136,I7,'Detailed Measures'!$X$3:$X$136) -> 1795.7882 | K7: =SUMIF('Detailed Measures'!$D$3:$D$136,I7,'Detailed Measures'!$Y$3:$Y$136) -> 20350.664 | L7: =K7/$K$18 -> 0.0096001644
A8: Net Present Value (project life) per Wp | B8: =B7/Inputs!D15 -> 0.21202216 | D8: PV module/array Specialist | E8: =SUMIF('Detailed Measures'!$J$3:$J$136,D8,'Detailed Measures'!$X$3:$X$136) -> 26303.453 | F8: =SUMIF('Detailed Measures'!$J$3:$J$136,D8,'Detailed Measures'!$Y$3:$Y$136) -> 318732.32 | G8: =F8/$F$18 -> 0.15032972 | I8: =Lists!C8 -> Mechanical | J8: =SUMIF('Detailed Measures'!$D$3:$D$136,I8,'Detailed Measures'!$X$3:$X$136) -> 5316.9973 | K8: =SUMIF('Detailed Measures'!$D$3:$D$136,I8,'Detailed Measures'!$Y$3:$Y$136) -> 53304.223 | L8: =K8/$K$18 -> 0.025145582
A9: NPV Annual O&M Cost per kWh | B9: =B7/NPV(Inputs!D6,'Detailed Measures'!AA138:BM138) -> 0.013451288 | D9: Network/IT | E9: =SUMIF('Detailed Measures'!$J$3:$J$136,D9,'Detailed Measures'!$X$3:$X$136) -> 152.40949 | F9: =SUMIF('Detailed Measures'!$J$3:$J$136,D9,'Detailed Measures'!$Y$3:$Y$136) -> 1530.5846 | G9: =F9/$F$18 -> 0.00072189844 | I9: =Lists!C9 -> Inverter | J9: =SUMIF('Detailed Measures'!$D$3:$D$136,I9,'Detailed Measures'!$X$3:$X$136) -> 30636.999 | K9: =SUMIF('Detailed Measures'!$D$3:$D$136,I9,'Detailed Measures'!$Y$3:$Y$136) -> 277163.57 | L9: =K9/$K$18 -> 0.13074835
D10: Master electrician | E10: =SUMIF('Detailed Measures'!$J$3:$J$136,D10,'Detailed Measures'!$X$3:$X$136) -> 4790.3476 | F10: =SUMIF('Detailed Measures'!$J$3:$J$136,D10,'Detailed Measures'!$Y$3:$Y$136) -> 53383.212 | G10: =F10/$F$18 -> 0.025178129 | I10: =Lists!C10 -> Meter | J10: =SUMIF('Detailed Measures'!$D$3:$D$136,I10,'Detailed Measures'!$X$3:$X$136) -> 17.809584 | K10: =SUMIF('Detailed Measures'!$D$3:$D$136,I10,'Detailed Measures'!$Y$3:$Y$136) -> 204.56695 | L10: =K10/$K$18 -> 9.6501831e-05
D11: Mechanic | E11: =SUMIF('Detailed Measures'!$J$3:$J$136,D11,'Detailed Measures'!$X$3:$X$136) -> 2207.3313 | F11: =SUMIF('Detailed Measures'!$J$3:$J$136,D11,'Detailed Measures'!$Y$3:$Y$136) -> 54081.586 | G11: =F11/$F$18 -> 0.025507516 | I11: =Lists!C11 -> Monitoring | J11: =SUMIF('Detailed Measures'!$D$3:$D$136,I11,'Detailed Measures'!$X$3:$X$136) -> 3.4091348 | K11: =SUMIF('Detailed Measures'!$D$3:$D$136,I11,'Detailed Measures'!$Y$3:$Y$136) -> 17.619704 | L11: =K11/$K$18 -> 8.3118691e-06
D12: Designer | E12: =SUMIF('Detailed Measures'!$J$3:$J$136,D12,'Detailed Measures'!$X$3:$X$136) -> 0 | F12: =SUMIF('Detailed Measures'!$J$3:$J$136,D12,'Detailed Measures'!$Y$3:$Y$136) -> 0 | G12: =F12/$F$18 -> 0 | I12: =Lists!C12 -> Roof | J12: =SUMIF('Detailed Measures'!$D$3:$D$136,I12,'Detailed Measures'!$X$3:$X$136) -> 0 | K12: =SUMIF('Detailed Measures'!$D$3:$D$136,I12,'Detailed Measures'!$Y$3:$Y$136) -> 0 | L12: =K12/$K$18 -> 0
D13: Pest control | E13: =SUMIF('Detailed Measures'!$J$3:$J$136,D13,'Detailed Measures'!$X$3:$X$136) -> 1613.7533 | F13: =SUMIF('Detailed Measures'!$J$3:$J$136,D13,'Detailed Measures'!$Y$3:$Y$136) -> 18536.12 | G13: =F13/$F$18 -> 0.0087425393 | I13: =Lists!C13 -> Rack | J13: =SUMIF('Detailed Measures'!$D$3:$D$136,I13,'Detailed Measures'!$X$3:$X$136) -> 105.71335 | K13: =SUMIF('Detailed Measures'!$D$3:$D$136,I13,'Detailed Measures'!$Y$3:$Y$136) -> 1220.7685 | L13: =K13/$K$18 -> 0.00057588183
D14: Roofing | E14: =SUMIF('Detailed Measures'!$J$3:$J$136,D14,'Detailed Measures'!$X$3:$X$136) -> 0 | F14: =SUMIF('Detailed Measures'!$J$3:$J$136,D14,'Detailed Measures'!$Y$3:$Y$136) -> 0 | G14: =F14/$F$18 -> 0 | I14: =Lists!C14 -> PV Module | J14: =SUMIF('Detailed Measures'!$D$3:$D$136,I14,'Detailed Measures'!$X$3:$X$136) -> 56090.654 | K14: =SUMIF('Detailed Measures'!$D$3:$D$136,I14,'Detailed Measures'!$Y$3:$Y$136) -> 1105116.1 | L14: =K14/$K$18 -> 0.52132431
D15: Structural engineer | E15: =SUMIF('Detailed Measures'!$J$3:$J$136,D15,'Detailed Measures'!$X$3:$X$136) -> 5.9545299 | F15: =SUMIF('Detailed Measures'!$J$3:$J$136,D15,'Detailed Measures'!$Y$3:$Y$136) -> 69.390865 | G15: =F15/$F$18 -> 3.2728119e-05 | I15: =Lists!C15 -> Tracker | J15: =SUMIF('Detailed Measures'!$D$3:$D$136,I15,'Detailed Measures'!$X$3:$X$136) -> 7547.5399 | K15: =SUMIF('Detailed Measures'!$D$3:$D$136,I15,'Detailed Measures'!$Y$3:$Y$136) -> 86693.618 | L15: =K15/$K$18 -> 0.0408966
D16: Mower/Trimmer | E16: =SUMIF('Detailed Measures'!$J$3:$J$136,D16,'Detailed Measures'!$X$3:$X$136) -> 15573.664 | F16: =SUMIF('Detailed Measures'!$J$3:$J$136,D16,'Detailed Measures'!$Y$3:$Y$136) -> 178884.42 | G16: =F16/$F$18 -> 0.084370626 | I16: =Lists!C16 -> Transformer | J16: =SUMIF('Detailed Measures'!$D$3:$D$136,I16,'Detailed Measures'!$X$3:$X$136) -> 4395.4969 | K16: =SUMIF('Detailed Measures'!$D$3:$D$136,I16,'Detailed Measures'!$Y$3:$Y$136) -> 49377.432 | L16: =K16/$K$18 -> 0.023293169
D17: Utilities locator | E17: =SUMIF('Detailed Measures'!$J$3:$J$136,D17,'Detailed Measures'!$X$3:$X$136) -> 4.3650024 | F17: =SUMIF('Detailed Measures'!$J$3:$J$136,D17,'Detailed Measures'!$Y$3:$Y$136) -> 44.497299 | G17: =F17/$F$18 -> 2.0987099e-05 | I17: =Lists!C17 -> Whole System | J17: =SUMIF('Detailed Measures'!$D$3:$D$136,I17,'Detailed Measures'!$X$3:$X$136) -> 35.453297 | K17: =SUMIF('Detailed Measures'!$D$3:$D$136,I17,'Detailed Measures'!$Y$3:$Y$136) -> 396.98139 | L17: =K17/$K$18 -> 0.00018727087
D18: Total | E18: =SUM(E3:E17) -> 148619.77 | F18: =SUM(F3:F17) -> 2120221.6 | G18: =SUM(G3:G17) -> 1 | I18: Total | J18: =SUM(J3:J16) -> 148584.32 | K18: =SUM(K3:K16) -> 2119824.6 | L18: =SUM(L3:L16) -> 1

Sheet Detailed Measures
A1: Detailed Measures | Y1: Annual Cash Flow | AA1: Annual Cash Flow | BO1: Reserve Account | BQ1: Reserve Account
A2: Service Description | B2: O&M Type | C2: Service Category | D2: O&M Category | E2: Applicable ? (1= yes, 0 = no) | F2: Covered by Warranty - Materials (1=yes, 0=no) | G2: Covered by Warranty - Labor (1=yes, 0=no) | H2: Warranty or Service Package Type | I2: Applicable Unit | J2: Service Provider | K2: Labor Rate per Hour | L2: Mean Interval (years) | M2: Weibull or Lognormal Shape Factor | N2: Type of Distribution | O2: Approx. Number of Units | P2: Labor hrs per unit | Q2: Total Labor Hours/year (not used, just for check) | R2: Material/ Other Cost per unit | S2: Total Labor Cost | T2: Total Matl and Other Cost | U2: Total Cost for Measure | V2: Notes | W2: Reference | X2: Average Annual Expense | Y2: NPV (Project Life) | Z2: % of Total NPV | AA2: 1 | AB2: 2 | AC2: 3 | AD2: 4 | AE2: 5 | AF2: 6 | AG2: 7 | AH2: 8 | AI2: 9 | AJ2: 10 | AK2: 11 | AL2: 12 | AM2: 13 | AN2: 14 | AO2: 15 | AP2: 16 | AQ2: 17 | AR2: 18 | AS2: 19 | AT2: 20 | AU2: 21 | AV2: 22 | AW2: 23 | AX2: 24 | AY2: 25 | AZ2: 26 | BA2: 27 | BB2: 28 | BC2: 29 | BD2: 30 | BE2: 31 | BF2: 32 | BG2: 33 | BH2: 34 | BI2: 35 | BJ2: 36 | BK2: 37 | BL2: 38 | BM2: 39 | BN2: 40 | BO2: NPV (Project Life) | BP2: % of Total NPV | BQ2: 1 | BR2: 2 | BS2: 3 | BT2: 4 | BU2: 5 | BV2: 6 | BW2: 7 | BX2: 8 | BY2: 9 | BZ2: 10 | CA2: 11 | CB2: 12 | CC2: 13 | CD2: 14 | CE2: 15 | CF2: 16 | CG2: 17 | CH2: 18 | CI2: 19 | CJ2: 20 | CK2: 21 | CL2: 22 | CM2: 23 | CN2: 24 | CO2: 25 | CP2: 26 | CQ2: 27 | CR2: 28 | CS2: 29 | CT2: 30 | CU2: 31 | CV2: 32 | CW2: 33 | CX2: 34 | CY2: 35 | CZ2: 36 | DA2: 37 | DB2: 38 | DC2: 39 | DD2: 40
A3: Insurance Premium | B3: Administration | C3: Management | D3: Asset Management | E3: 1 | F3: 0 | G3: 0 | H3: N/A | I3: percent of initial cost | J3: Administrator | K3: =VLOOKUP(J3,'Labor Rates'!$A$1:$F$16,2) -> 22.995577 | L3: 1 | M3: 1 | N3: interval | O3: 1 | P3: 0 | Q3: =O3*P3/L3 -> 0 | R3: =0.001*Inputs!D17 -> 3000 | S3: =P3*O3*K3 -> 0 | T3: =R3*O3 -> 3000 | U3: =E3*(T3+S3) -> 3000 | V3: premium percent of intial cost.04% | W3: David Walters, Hartford Steam Boiler, 6/7/2014 | X3: =AVERAGE(AA3:AT3) -> 3717.4976 | Y3: =NPV(Inputs!$D$6,AA3:BN3) -> 42700.445 | Z3: =Y3/SUM($Y$3:$Y$136) -> 0.020139615 | AA3: =$E3*IF(AA$2>Inputs!$D$5,0,IF(AA$2>VLOOKUP($H3,Lists!$P$3:$Q$7,2),IF($N3=Lists!$K$3,IF($L3<1,(($U3/$L3)*((1+Inputs!$D$7)^AA$2)),((INT(AA$2/$L3)-INT((AA$2-1)/$L3))*$U3*((1+Inputs!$D$7)^AA$2))),(_xlfn.WEIBULL.DIST(AA$2,$M3,$L3,FALSE)*$U3*((1+Inputs!$D$7)^AA$2))),IF($N3=Lists!$K$3,IF($L3<1,((($T3*(1-$F3)+$S3*(1-$G3))/$L3)*((1+Inputs!$D$7)^AA$2)),((INT(AA$2/$L3)-INT((AA$2-1)/$L3))*($T3*(1-$F3)+$S3*(1-$G3))*((1+Inputs!$D$7)^AA$2))),((_xlfn.WEIBULL.DIST(AA$2,$M3,$L3,FALSE)*($T3*(1-$F3)+$S3*(1-$G3))*((1+Inputs!$D$7)^AA$2)))))) -> 3060 | AB3: =$E3*IF(AB$2>Inputs!$D$5,0,IF(AB$2>VLOOKUP($H3,Lists!$P$3:$Q$7,2),IF($N3=Lists!$K$3,IF($L3<1,(($U3/$L3)*((1+Inputs!$D$7)^AB$2)),((INT(AB$2/$L3)-INT((AB$2-1)/$L3))*$U3*((1+Inputs!$D$7)^AB$2))),(_xlfn.WEIBULL.DIST(AB$2,$M3,$L3,FALSE)*$U3*((1+Inputs!$D$7)^AB$2))),IF($N3=Lists!$K$3,IF($L3<1,((($T3*(1-$F3)+$S3*(1-$G3))/$L3)*((1+Inputs!$D$7)^AB$2)),((INT(AB$2/$L3)-INT((AB$2-1)/$L3))*($T3*(1-$F3)+$S3*(1-$G3))*((1+Inputs!$D$7)^AB$2))),((_xlfn.WEIBULL.DIST(AB$2,$M3,$L3,FALSE)*($T3*(1-$F3)+$S3*(1-$G3))*((1+Inputs!$D$7)^AB$2)))))) -> 3121.2 | AC3: =$E3*IF(AC$2>Inputs!$D$5,0,IF(AC$2>VLOOKUP($H3,Lists!$P$3:$Q$7,2),IF($N3=Lists!$K$3,IF($L3<1,(($U3/$L3)*((1+Inputs!$D$7)^AC$2)),((INT(AC$2/$L3)-INT((AC$2-1)/$L3))*$U3*((1+Inputs!$D$7)^AC$2))),(_xlfn.WEIBULL.DIST(AC$2,$M3,$L3,FALSE)*$U3*((1+Inputs!$D$7)^AC$2))),IF($N3=Lists!$K$3,IF($L3<1,((($T3*(1-$F3)+$S3*(1-$G3))/$L3)*((1+Inputs!$D$7)^AC$2)),((INT(AC$2/$L3)-INT((AC$2-1)/$L3))*($T3*(1-$F3)+$S3*(1-$G3))*((1+Inputs!$D$7)^AC$2))),((_xlfn.WEIBULL.DIST(AC$2,$M3,$L3,FALSE)*($T3*(1-$F3)+$S3*(1-$G3))*((1+Inputs!$D$7)^AC$2)))))) -> 3183.624 | AD3: =$E3*IF(AD$2>Inputs!$D$5,0,IF(AD$2>VLOOKUP($H3,Lists!$P$3:$Q$7,2),IF($N3=Lists!$K$3,IF($L3<1,(($U3/$L3)*((1+Inputs!$D$7)^AD$2)),((INT(AD$2/$L3)-INT((AD$2-1)/$L3))*$U3*((1+Inputs!$D$7)^AD$2))),Inputs!$D$85^((1-_xlfn.WEIBULL.DIST(AD$2,$M3,$L3,FALSE))/_xlfn.WEIBULL.DIST(AD$2,$M3,$L3,FALSE)*$U3*((1+Inputs!$D$7)^AD$2))),IF($N3=Lists!$K$3,IF($L3<1,((($T3*(1-$F3)+$S3*(1-$G3))/$L3)*((1+Inputs!$D$7)^AD$2)),((INT(AD$2/$L3)-INT((AD$2-1)/$L3))*($T3*(1-$F3)+$S3*(1-$G3))*((1+Inputs!$D$7)^AD$2))),((Inputs!$D$85^((1-_xlfn.WEIBULL.DIST(AD$2,$M3,$L3,FALSE))/_xlfn.WEIBULL.DIST(AD$2,$M3,$L3,FALSE)*($T3*(1-$F3)+$S3*(1-$G3))*((1+Inputs!$D$7)^AD$2))))))) -> 3247.2965 | AE3: =$E3*IF(AE$2>Inputs!$D$5,0,IF(AE$2>VLOOKUP($H3,Lists!$P$3:$Q$7,2),IF($N3=Lists!$K$3,IF($L3<1,(($U3/$L3)*((1+Inputs!$D$7)^AE$2)),((INT(AE$2/$L3)-INT((AE$2-1)/$L3))*$U3*((1+Inputs!$D$7)^AE$2))),(_xlfn.WEIBULL.DIST(AE$2,$M3,$L3,FALSE)*$U3*((1+Inputs!$D$7)^AE$2))),IF($N3=Lists!$K$3,IF($L3<1,((($T3*(1-$F3)+$S3*(1-$G3))/$L3)*((1+Inputs!$D$7)^AE$2)),((INT(AE$2/$L3)-INT((AE$2-1)/$L3))*($T3*(1-$F3)+$S3*(1-$G3))*((1+Inputs!$D$7)^AE$2))),((_xlfn.WEIBULL.DIST(AE$2,$M3,$L3,FALSE)*($T3*(1-$F3)+$S3*(1-$G3))*((1+Inputs!$D$7)^AE$2)))))) -> 3312.2424 | AF3: =$E3*IF(AF$2>Inputs!$D$5,0,IF(AF$2>VLOOKUP($H3,Lists!$P$3:$Q$7,2),IF($N3=Lists!$K$3,IF($L3<1,(($U3/$L3)*((1+Inputs!$D$7)^AF$2)),((INT(AF$2/$L3)-INT((AF$2-1)/$L3))*$U3*((1+Inputs!$D$7)^AF$2))),(_xlfn.WEIBULL.DIST(AF$2,$M3,$L3,FALSE)*$U3*((1+Inputs!$D$7)^AF$2))),IF($N3=Lists!$K$3,IF($L3<1,((($T3*(1-$F3)+$S3*(1-$G3))/$L3)*((1+Inputs!$D$7)^AF$2)),((INT(AF$2/$L3)-INT((AF$2-1)/$L3))*($T3*(1-$F3)+$S3*(1-$G3))*((1+Inputs!$D$7)^AF$2))),((_xlfn.WEIBULL.DIST(AF$2,$M3,$L3,FALSE)*($T3*(1-$F3)+$S3*(1-$G3))*((1+Inputs!$D$7)^AF$2)))))) -> 3378.4873 | AG3: =$E3*IF(AG$2>Inputs!$D$5,0,IF(AG$2>VLOOKUP($H3,Lists!$P$3:$Q$7,2),IF($N3=Lists!$K$3,IF($L3<1,(($U3/$L3)*((1+Inputs!$D$7)^AG$2)),((INT(AG$2/$L3)-INT((AG$2-1)/$L3))*$U3*((1+Inputs!$D$7)^AG$2))),(_xlfn.WEIBULL.DIST(AG$2,$M3,$L3,FALSE)*$U3*((1+Inputs!$D$7)^AG$2))),IF($N3=Lists!$K$3,IF($L3<1,((($T3*(1-$F3)+$S3*(1-$G3))/$L3)*((1+Inputs!$D$7)^AG$2)),((INT(AG$2/$L3)-INT((AG$2-1)/$L3))*($T3*(1-$F3)+$S3*(1-$G3))*((1+Inputs!$D$7)^AG$2))),((_xlfn.WEIBULL.DIST(AG$2,$M3,$L3,FALSE)*($T3*(1-$F3)+$S3*(1-$G3))*((1+Inputs!$D$7)^AG$2)))))) -> 3446.057 | AH3: =$E3*IF(AH$2>Inputs!$D$5,0,IF(AH$2>VLOOKUP($H3,Lists!$P$3:$Q$7,2),IF($N3=Lists!$K$3,IF($L3<1,(($U3/$L3)*((1+Inputs!$D$7)^AH$2)),((INT(AH$2/$L3)-INT((AH$2-1)/$L3))*$U3*((1+Inputs!$D$7)^AH$2))),(_xlfn.WEIBULL.DIST(AH$2,$M3,$L3,FALSE)*$U3*((1+Inputs!$D$7)^AH$2))),IF($N3=Lists!$K$3,IF($L3<1,((($T3*(1-$F3)+$S3*(1-$G3))/$L3)*((1+Inputs!$D$7)^AH$2)),((INT(AH$2/$L3)-INT((AH$2-1)/$L3))*($T3*(1-$F3)+$S3*(1-$G3))*((1+Inputs!$D$7)^AH$2))),((_xlfn.WEIBULL.DIST(AH$2,$M3,$L3,FALSE)*($T3*(1-$F3)+$S3*(1-$G3))*((1+Inputs!$D$7)^AH$2)))))) -> 3514.9781 | AI3: =$E3*IF(AI$2>Inputs!$D$5,0,IF(AI$2>VLOOKUP($H3,Lists!$P$3:$Q$7,2),IF($N3=Lists!$K$3,IF($L3<1,(($U3/$L3)*((1+Inputs!$D$7)^AI$2)),((INT(AI$2/$L3)-INT((AI$2-1)/$L3))*$U3*((1+Inputs!$D$7)^AI$2))),(_xlfn.WEIBULL.DIST(AI$2,$M3,$L3,FALSE)*$U3*((1+Inputs!$D$7)^AI$2))),IF($N3=Lists!$K$3,IF($L3<1,((($T3*(1-$F3)+$S3*(1-$G3))/$L3)*((1+Inputs!$D$7)^AI$2)),((INT(AI$2/$L3)-INT((AI$2-1)/$L3))*($T3*(1-$F3)+$S3*(1-$G3))*((1+Inputs!$D$7)^AI$2))),((_xlfn.WEIBULL.DIST(AI$2,$M3,$L3,FALSE)*($T3*(1-$F3)+$S3*(1-$G3))*((1+Inputs!$D$7)^AI$2)))))) -> 3585.2777 | AJ3: =$E3*IF(AJ$2>Inputs!$D$5,0,IF(AJ$2>VLOOKUP($H3,Lists!$P$3:$Q$7,2),IF($N3=Lists!$K$3,IF($L3<1,(($U3/$L3)*((1+Inputs!$D$7)^AJ$2)),((INT(AJ$2/$L3)-INT((AJ$2-1)/$L3))*$U3*((1+Inputs!$D$7)^AJ$2))),(_xlfn.WEIBULL.DIST(AJ$2,$M3,$L3,FALSE)*$U3*((1+Inputs!$D$7)^AJ$2))),IF($N3=Lists!$K$3,IF($L3<1,((($T3*(1-$F3)+$S3*(1-$G3))/$L3)*((1+Inputs!$D$7)^AJ$2)),((INT(AJ$2/$L3)-INT((AJ$2-1)/$L3))*($T3*(1-$F3)+$S3*(1-$G3))*((1+Inputs!$D$7)^AJ$2))),((_xlfn.WEIBULL.DIST(AJ$2,$M3,$L3,FALSE)*($T3*(1-$F3)+$S3*(1-$G3))*((1+Inputs!$D$7)^AJ$2)))))) -> 3656.9833 | AK3: =$E3*IF(AK$2>Inputs!$D$5,0,IF(AK$2>VLOOKUP($H3,Lists!$P$3:$Q$7,2),IF($N3=Lists!$K$3,IF($L3<1,(($U3/$L3)*((1+Inputs!$D$7)^AK$2)),((INT(AK$2/$L3)-INT((AK$2-1)/$L3))*$U3*((1+Inputs!$D$7)^AK$2))),(_xlfn.WEIBULL.DIST(AK$2,$M3,$L3,FALSE)*$U3*((1+Inputs!$D$7)^AK$2))),IF($N3=Lists!$K$3,IF($L3<1,((($T3*(1-$F3)+$S3*(1-$G3))/$L3)*((1+Inputs!$D$7)^AK$2)),((INT(AK$2/$L3)-INT((AK$2-1)/$L3))*($T3*(1-$F3)+$S3*(1-$G3))*((1+Inputs!$D$7)^AK$2))),((_xlfn.WEIBULL.DIST(AK$2,$M3,$L3,FALSE)*($T3*(1-$F3)+$S3*(1-$G3))*((1+Inputs!$D$7)^AK$2)))))) -> 3730.1229 | AL3: =$E3*IF(AL$2>Inputs!$D$5,0,IF(AL$2>VLOOKUP($H3,Lists!$P$3:$Q$7,2),IF($N3=Lists!$K$3,IF($L3<1,(($U3/$L3)*((1+Inputs!$D$7)^AL$2)),((INT(AL$2/$L3)-INT((AL$2-1)/$L3))*$U3*((1+Inputs!$D$7)^AL$2))),(_xlfn.WEIBULL.DIST(AL$2,$M3,$L3,FALSE)*$U3*((1+Inputs!$D$7)^AL$2))),IF($N3=Lists!$K$3,IF($L3<1,((($T3*(1-$F3)+$S3*(1-$G3))/$L3)*((1+Inputs!$D$7)^AL$2)),((INT(AL$2/$L3)-INT((AL$2-1)/$L3))*($T3*(1-$F3)+$S3*(1-$G3))*((1+Inputs!$D$7)^AL$2))),((_xlfn.WEIBULL.DIST(AL$2,$M3,$L3,FALSE)*($T3*(1-$F3)+$S3*(1-$G3))*((1+Inputs!$D$7)^AL$2)))))) -> 3804.7254 | ... BN3: =$E3*IF(BN$2>Inputs!$D$5,0,IF(BN$2>VLOOKUP($H3,Lists!$P$3:$Q$7,2),IF($N3=Lists!$K$3,IF($L3<1,(($U3/$L3)*((1+Inputs!$D$7)^BN$2)),((INT(BN$2/$L3)-INT((BN$2-1)/$L3))*$U3*((1+Inputs!$D$7)^BN$2))),(_xlfn.WEIBULL.DIST(BN$2,$M3,$L3,FALSE)*$U3*((1+Inputs!$D$7)^BN$2))),IF($N3=Lists!$K$3,IF($L3<1,((($T3*(1-$F3)+$S3*(1-$G3))/$L3)*((1+Inputs!$D$7)^BN$2)),((INT(BN$2/$L3)-INT((BN$2-1)/$L3))*($T3*(1-$F3)+$S3*(1-$G3))*((1+Inputs!$D$7)^BN$2))),((_xlfn.WEIBULL.DIST(BN$2,$M3,$L3,FALSE)*($T3*(1-$F3)+$S3*(1-$G3))*((1+Inputs!$D$7)^BN$2)))))) -> 0 | BO3: =NPV(Inputs!$D$6,BQ3:DD3) -> 42700.445 | BP3: =BO3/SUM($Y$3:$Y$136) -> 0.020139615 | BQ3: =MAX(AA3,($E3*IF(BQ$2>Inputs!$D$5,0,IF(BQ$2>VLOOKUP($H3,Lists!$P$3:$Q$7,2),IF($N3=Lists!$K$3,IF($L3<1,(($U3/$L3)*((1+Inputs!$D$7)^BQ$2)),((INT(BQ$2/$L3)-INT((BQ$2-1)/$L3))*$U3*((1+Inputs!$D$7)^BQ$2))),(Inputs!$D$8^((1-_xlfn.WEIBULL.DIST(BQ$2,$M3,$L3,FALSE))/_xlfn.WEIBULL.DIST(BQ$2,$M3,$L3,FALSE))*$U3*((1+Inputs!$D$7)^BQ$2))),IF($N3=Lists!$K$3,IF($L3<1,((($T3*(1-$F3)+$S3*(1-$G3))/$L3)*((1+Inputs!$D$7)^BQ$2)),((INT(BQ$2/$L3)-INT((BQ$2-1)/$L3))*($T3*(1-$F3)+$S3*(1-$G3))*((1+Inputs!$D$7)^BQ$2))),((Inputs!$D$8^((1-_xlfn.WEIBULL.DIST(BQ$2,$M3,$L3,FALSE))/_xlfn.WEIBULL.DIST(BQ$2,$M3,$L3,FALSE))*($T3*(1-$F3)+$S3*(1-$G3))*((1+Inputs!$D$7)^BQ$2)))))))) -> 3060 | BR3: =MAX(AB3,($E3*IF(BR$2>Inputs!$D$5,0,IF(BR$2>VLOOKUP($H3,Lists!$P$3:$Q$7,2),IF($N3=Lists!$K$3,IF($L3<1,(($U3/$L3)*((1+Inputs!$D$7)^BR$2)),((INT(BR$2/$L3)-INT((BR$2-1)/$L3))*$U3*((1+Inputs!$D$7)^BR$2))),(Inputs!$D$8^((1-_xlfn.WEIBULL.DIST(BR$2,$M3,$L3,FALSE))/_xlfn.WEIBULL.DIST(BR$2,$M3,$L3,FALSE))*$U3*((1+Inputs!$D$7)^BR$2))),IF($N3=Lists!$K$3,IF($L3<1,((($T3*(1-$F3)+$S3*(1-$G3))/$L3)*((1+Inputs!$D$7)^BR$2)),((INT(BR$2/$L3)-INT((BR$2-1)/$L3))*($T3*(1-$F3)+$S3*(1-$G3))*((1+Inputs!$D$7)^BR$2))),((Inputs!$D$8^((1-_xlfn.WEIBULL.DIST(BR$2,$M3,$L3,FALSE))/_xlfn.WEIBULL.DIST(BR$2,$M3,$L3,FALSE))*($T3*(1-$F3)+$S3*(1-$G3))*((1+Inputs!$D$7)^BR$2)))))))) -> 3121.2 | BS3: =MAX(AC3,($E3*IF(BS$2>Inputs!$D$5,0,IF(BS$2>VLOOKUP($H3,Lists!$P$3:$Q$7,2),IF($N3=Lists!$K$3,IF($L3<1,(($U3/$L3)*((1+Inputs!$D$7)^BS$2)),((INT(BS$2/$L3)-INT((BS$2-1)/$L3))*$U3*((1+Inputs!$D$7)^BS$2))),(Inputs!$D$8^((1-_xlfn.WEIBULL.DIST(BS$2,$M3,$L3,FALSE))/_xlfn.WEIBULL.DIST(BS$2,$M3,$L3,FALSE))*$U3*((1+Inputs!$D$7)^BS$2))),IF($N3=Lists!$K$3,IF($L3<1,((($T3*(1-$F3)+$S3*(1-$G3))/$L3)*((1+Inputs!$D$7)^BS$2)),((INT(BS$2/$L3)-INT((BS$2-1)/$L3))*($T3*(1-$F3)+$S3*(1-$G3))*((1+Inputs!$D$7)^BS$2))),((Inputs!$D$8^((1-_xlfn.WEIBULL.DIST(BS$2,$M3,$L3,FALSE))/_xlfn.WEIBULL.DIST(BS$2,$M3,$L3,FALSE))*($T3*(1-$F3)+$S3*(1-$G3))*((1+Inputs!$D$7)^BS$2)))))))) -> 3183.624 | BT3: =MAX(AD3,($E3*IF(BT$2>Inputs!$D$5,0,IF(BT$2>VLOOKUP($H3,Lists!$P$3:$Q$7,2),IF($N3=Lists!$K$3,IF($L3<1,(($U3/$L3)*((1+Inputs!$D$7)^BT$2)),((INT(BT$2/$L3)-INT((BT$2-1)/$L3))*$U3*((1+Inputs!$D$7)^BT$2))),(Inputs!$D$8^((1-_xlfn.WEIBULL.DIST(BT$2,$M3,$L3,FALSE))/_xlfn.WEIBULL.DIST(BT$2,$M3,$L3,FALSE))*$U3*((1+Inputs!$D$7)^BT$2))),IF($N3=Lists!$K$3,IF($L3<1,((($T3*(1-$F3)+$S3*(1-$G3))/$L3)*((1+Inputs!$D$7)^BT$2)),((INT(BT$2/$L3)-INT((BT$2-1)/$L3))*($T3*(1-$F3)+$S3*(1-$G3))*((1+Inputs!$D$7)^BT$2))),((Inputs!$D$8^((1-_xlfn.WEIBULL.DIST(BT$2,$M3,$L3,FALSE))/_xlfn.WEIBULL.DIST(BT$2,$M3,$L3,FALSE))*($T3*(1-$F3)+$S3*(1-$G3))*((1+Inputs!$D$7)^BT$2)))))))) -> 3247.2965 | BU3: =MAX(AE3,($E3*IF(BU$2>Inputs!$D$5,0,IF(BU$2>VLOOKUP($H3,Lists!$P$3:$Q$7,2),IF($N3=Lists!$K$3,IF($L3<1,(($U3/$L3)*((1+Inputs!$D$7)^BU$2)),((INT(BU$2/$L3)-INT((BU$2-1)/$L3))*$U3*((1+Inputs!$D$7)^BU$2))),(Inputs!$D$8^((1-_xlfn.WEIBULL.DIST(BU$2,$M3,$L3,FALSE))/_xlfn.WEIBULL.DIST(BU$2,$M3,$L3,FALSE))*$U3*((1+Inputs!$D$7)^BU$2))),IF($N3=Lists!$K$3,IF($L3<1,((($T3*(1-$F3)+$S3*(1-$G3))/$L3)*((1+Inputs!$D$7)^BU$2)),((INT(BU$2/$L3)-INT((BU$2-1)/$L3))*($T3*(1-$F3)+$S3*(1-$G3))*((1+Inputs!$D$7)^BU$2))),((Inputs!$D$8^((1-_xlfn.WEIBULL.DIST(BU$2,$M3,$L3,FALSE))/_xlfn.WEIBULL.DIST(BU$2,$M3,$L3,FALSE))*($T3*(1-$F3)+$S3*(1-$G3))*((1+Inputs!$D$7)^BU$2)))))))) -> 3312.2424 | BV3: =MAX(AF3,($E3*IF(BV$2>Inputs!$D$5,0,IF(BV$2>VLOOKUP($H3,Lists!$P$3:$Q$7,2),IF($N3=Lists!$K$3,IF($L3<1,(($U3/$L3)*((1+Inputs!$D$7)^BV$2)),((INT(BV$2/$L3)-INT((BV$2-1)/$L3))*$U3*((1+Inputs!$D$7)^BV$2))),(Inputs!$D$8^((1-_xlfn.WEIBULL.DIST(BV$2,$M3,$L3,FALSE))/_xlfn.WEIBULL.DIST(BV$2,$M3,$L3,FALSE))*$U3*((1+Inputs!$D$7)^BV$2))),IF($N3=Lists!$K$3,IF($L3<1,((($T3*(1-$F3)+$S3*(1-$G3))/$L3)*((1+Inputs!$D$7)^BV$2)),((INT(BV$2/$L3)-INT((BV$2-1)/$L3))*($T3*(1-$F3)+$S3*(1-$G3))*((1+Inputs!$D$7)^BV$2))),((Inputs!$D$8^((1-_xlfn.WEIBULL.DIST(BV$2,$M3,$L3,FALSE))/_xlfn.WEIBULL.DIST(BV$2,$M3,$L3,FALSE))*($T3*(1-$F3)+$S3*(1-$G3))*((1+Inputs!$D$7)^BV$2)))))))) -> 3378.4873 | BW3: =MAX(AG3,($E3*IF(BW$2>Inputs!$D$5,0,IF(BW$2>VLOOKUP($H3,Lists!$P$3:$Q$7,2),IF($N3=Lists!$K$3,IF($L3<1,(($U3/$L3)*((1+Inputs!$D$7)^BW$2)),((INT(BW$2/$L3)-INT((BW$2-1)/$L3))*$U3*((1+Inputs!$D$7)^BW$2))),(Inputs!$D$8^((1-_xlfn.WEIBULL.DIST(BW$2,$M3,$L3,FALSE))/_xlfn.WEIBULL.DIST(BW$2,$M3,$L3,FALSE))*$U3*((1+Inputs!$D$7)^BW$2))),IF($N3=Lists!$K$3,IF($L3<1,((($T3*(1-$F3)+$S3*(1-$G3))/$L3)*((1+Inputs!$D$7)^BW$2)),((INT(BW$2/$L3)-INT((BW$2-1)/$L3))*($T3*(1-$F3)+$S3*(1-$G3))*((1+Inputs!$D$7)^BW$2))),((Inputs!$D$8^((1-_xlfn.WEIBULL.DIST(BW$2,$M3,$L3,FALSE))/_xlfn.WEIBULL.DIST(BW$2,$M3,$L3,FALSE))*($T3*(1-$F3)+$S3*(1-$G3))*((1+Inputs!$D$7)^BW$2)))))))) -> 3446.057 | BX3: =MAX(AH3,($E3*IF(BX$2>Inputs!$D$5,0,IF(BX$2>VLOOKUP($H3,Lists!$P$3:$Q$7,2),IF($N3=Lists!$K$3,IF($L3<1,(($U3/$L3)*((1+Inputs!$D$7)^BX$2)),((INT(BX$2/$L3)-INT((BX$2-1)/$L3))*$U3*((1+Inputs!$D$7)^BX$2))),(Inputs!$D$8^((1-_xlfn.WEIBULL.DIST(BX$2,$M3,$L3,FALSE))/_xlfn.WEIBULL.DIST(BX$2,$M3,$L3,FALSE))*$U3*((1+Inputs!$D$7)^BX$2))),IF($N3=Lists!$K$3,IF($L3<1,((($T3*(1-$F3)+$S3*(1-$G3))/$L3)*((1+Inputs!$D$7)^BX$2)),((INT(BX$2/$L3)-INT((BX$2-1)/$L3))*($T3*(1-$F3)+$S3*(1-$G3))*((1+Inputs!$D$7)^BX$2))),((Inputs!$D$8^((1-_xlfn.WEIBULL.DIST(BX$2,$M3,$L3,FALSE))/_xlfn.WEIBULL.DIST(BX$2,$M3,$L3,FALSE))*($T3*(1-$F3)+$S3*(1-$G3))*((1+Inputs!$D$7)^BX$2)))))))) -> 3514.9781 | ... DD3: =MAX(BN3,($E3*IF(DD$2>Inputs!$D$5,0,IF(DD$2>VLOOKUP($H3,Lists!$P$3:$Q$7,2),IF($N3=Lists!$K$3,IF($L3<1,(($U3/$L3)*((1+Inputs!$D$7)^DD$2)),((INT(DD$2/$L3)-INT((DD$2-1)/$L3))*$U3*((1+Inputs!$D$7)^DD$2))),(Inputs!$D$8^((1-_xlfn.WEIBULL.DIST(DD$2,$M3,$L3,FALSE))/_xlfn.WEIBULL.DIST(DD$2,$M3,$L3,FALSE))*$U3*((1+Inputs!$D$7)^DD$2))),IF($N3=Lists!$K$3,IF($L3<1,((($T3*(1-$F3)+$S3*(1-$G3))/$L3)*((1+Inputs!$D$7)^DD$2)),((INT(DD$2/$L3)-INT((DD$2-1)/$L3))*($T3*(1-$F3)+$S3*(1-$G3))*((1+Inputs!$D$7)^DD$2))),((Inputs!$D$8^((1-_xlfn.WEIBULL.DIST(DD$2,$M3,$L3,FALSE))/_xlfn.WEIBULL.DIST(DD$2,$M3,$L3,FALSE))*($T3*(1-$F3)+$S3*(1-$G3))*((1+Inputs!$D$7)^DD$2)))))))) -> 0
A4: Manage inventory of spare parts | B4: Administration | C4: Management | D4: Asset Management | E4: =IF(Inputs!$D$41=Lists!$I$4,0,1) -> 1 | F4: 0 | G4: 0 | H4: Monitoring | J4: Administrator | K4: =VLOOKUP(J4,'Labor Rates'!$A$1:$F$16,2) -> 22.995577 | L4: 0.5 | M4: 1 | N4: interval | O4: 1 | P4: 1 | Q4: =O4*P4/L4 -> 2 | R4: 0 | S4: =P4*O4*K4 -> 22.995577 | T4: =R4*O4 -> 0 | U4: =E4*(T4+S4) -> 22.995577 | X4: =AVERAGE(AA4:AT4) -> 56.990668 | Y4: =NPV(Inputs!$D$6,AA4:BN4) -> 654.61425 | Z4: =Y4/SUM($Y$3:$Y$136) -> 0.00030874804 | AA4: =$E4*IF(AA$2>Inputs!$D$5,0,IF(AA$2>VLOOKUP($H4,Lists!$P$3:$Q$7,2),IF($N4=Lists!$K$3,IF($L4<1,(($U4/$L4)*((1+Inputs!$D$7)^AA$2)),((INT(AA$2/$L4)-INT((AA$2-1)/$L4))*$U4*((1+Inputs!$D$7)^AA$2))),(_xlfn.WEIBULL.DIST(AA$2,$M4,$L4,FALSE)*$U4*((1+Inputs!$D$7)^AA$2))),IF($N4=Lists!$K$3,IF($L4<1,((($T4*(1-$F4)+$S4*(1-$G4))/$L4)*((1+Inputs!$D$7)^AA$2)),((INT(AA$2/$L4)-INT((AA$2-1)/$L4))*($T4*(1-$F4)+$S4*(1-$G4))*((1+Inputs!$D$7)^AA$2))),((_xlfn.WEIBULL.DIST(AA$2,$M4,$L4,FALSE)*($T4*(1-$F4)+$S4*(1-$G4))*((1+Inputs!$D$7)^AA$2)))))) -> 46.910977 | AB4: =$E4*IF(AB$2>Inputs!$D$5,0,IF(AB$2>VLOOKUP($H4,Lists!$P$3:$Q$7,2),IF($N4=Lists!$K$3,IF($L4<1,(($U4/$L4)*((1+Inputs!$D$7)^AB$2)),((INT(AB$2/$L4)-INT((AB$2-1)/$L4))*$U4*((1+Inputs!$D$7)^AB$2))),(_xlfn.WEIBULL.DIST(AB$2,$M4,$L4,FALSE)*$U4*((1+Inputs!$D$7)^AB$2))),IF($N4=Lists!$K$3,IF($L4<1,((($T4*(1-$F4)+$S4*(1-$G4))/$L4)*((1+Inputs!$D$7)^AB$2)),((INT(AB$2/$L4)-INT((AB$2-1)/$L4))*($T4*(1-$F4)+$S4*(1-$G4))*((1+Inputs!$D$7)^AB$2))),((_xlfn.WEIBULL.DIST(AB$2,$M4,$L4,FALSE)*($T4*(1-$F4)+$S4*(1-$G4))*((1+Inputs!$D$7)^AB$2)))))) -> 47.849196 | AC4: =$E4*IF(AC$2>Inputs!$D$5,0,IF(AC$2>VLOOKUP($H4,Lists!$P$3:$Q$7,2),IF($N4=Lists!$K$3,IF($L4<1,(($U4/$L4)*((1+Inputs!$D$7)^AC$2)),((INT(AC$2/$L4)-INT((AC$2-1)/$L4))*$U4*((1+Inputs!$D$7)^AC$2))),(_xlfn.WEIBULL.DIST(AC$2,$M4,$L4,FALSE)*$U4*((1+Inputs!$D$7)^AC$2))),IF($N4=Lists!$K$3,IF($L4<1,((($T4*(1-$F4)+$S4*(1-$G4))/$L4)*((1+Inputs!$D$7)^AC$2)),((INT(AC$2/$L4)-INT((AC$2-1)/$L4))*($T4*(1-$F4)+$S4*(1-$G4))*((1+Inputs!$D$7)^AC$2))),((_xlfn.WEIBULL.DIST(AC$2,$M4,$L4,FALSE)*($T4*(1-$F4)+$S4*(1-$G4))*((1+Inputs!$D$7)^AC$2)))))) -> 48.80618 | AD4: =$E4*IF(AD$2>Inputs!$D$5,0,IF(AD$2>VLOOKUP($H4,Lists!$P$3:$Q$7,2),IF($N4=Lists!$K$3,IF($L4<1,(($U4/$L4)*((1+Inputs!$D$7)^AD$2)),((INT(AD$2/$L4)-INT((AD$2-1)/$L4))*$U4*((1+Inputs!$D$7)^AD$2))),(_xlfn.WEIBULL.DIST(AD$2,$M4,$L4,FALSE)*$U4*((1+Inputs!$D$7)^AD$2))),IF($N4=Lists!$K$3,IF($L4<1,((($T4*(1-$F4)+$S4*(1-$G4))/$L4)*((1+Inputs!$D$7)^AD$2)),((INT(AD$2/$L4)-INT((AD$2-1)/$L4))*($T4*(1-$F4)+$S4*(1-$G4))*((1+Inputs!$D$7)^AD$2))),((_xlfn.WEIBULL.DIST(AD$2,$M4,$L4,FALSE)*($T4*(1-$F4)+$S4*(1-$G4))*((1+Inputs!$D$7)^AD$2)))))) -> 49.782304 | AE4: =$E4*IF(AE$2>Inputs!$D$5,0,IF(AE$2>VLOOKUP($H4,Lists!$P$3:$Q$7,2),IF($N4=Lists!$K$3,IF($L4<1,(($U4/$L4)*((1+Inputs!$D$7)^AE$2)),((INT(AE$2/$L4)-INT((AE$2-1)/$L4))*$U4*((1+Inputs!$D$7)^AE$2))),(_xlfn.WEIBULL.DIST(AE$2,$M4,$L4,FALSE)*$U4*((1+Inputs!$D$7)^AE$2))),IF($N4=Lists!$K$3,IF($L4<1,((($T4*(1-$F4)+$S4*(1-$G4))/$L4)*((1+Inputs!$D$7)^AE$2)),((INT(AE$2/$L4)-INT((AE$2-1)/$L4))*($T4*(1-$F4)+$S4*(1-$G4))*((1+Inputs!$D$7)^AE$2))),((_xlfn.WEIBULL.DIST(AE$2,$M4,$L4,FALSE)*($T4*(1-$F4)+$S4*(1-$G4))*((1+Inputs!$D$7)^AE$2)))))) -> 50.77795 | AF4: =$E4*IF(AF$2>Inputs!$D$5,0,IF(AF$2>VLOOKUP($H4,Lists!$P$3:$Q$7,2),IF($N4=Lists!$K$3,IF($L4<1,(($U4/$L4)*((1+Inputs!$D$7)^AF$2)),((INT(AF$2/$L4)-INT((AF$2-1)/$L4))*$U4*((1+Inputs!$D$7)^AF$2))),(_xlfn.WEIBULL.DIST(AF$2,$M4,$L4,FALSE)*$U4*((1+Inputs!$D$7)^AF$2))),IF($N4=Lists!$K$3,IF($L4<1,((($T4*(1-$F4)+$S4*(1-$G4))/$L4)*((1+Inputs!$D$7)^AF$2)),((INT(AF$2/$L4)-INT((AF$2-1)/$L4))*($T4*(1-$F4)+$S4*(1-$G4))*((1+Inputs!$D$7)^AF$2))),((_xlfn.WEIBULL.DIST(AF$2,$M4,$L4,FALSE)*($T4*(1-$F4)+$S4*(1-$G4))*((1+Inputs!$D$7)^AF$2)))))) -> 51.793509 | AG4: =$E4*IF(AG$2>Inputs!$D$5,0,IF(AG$2>VLOOKUP($H4,Lists!$P$3:$Q$7,2),IF($N4=Lists!$K$3,IF($L4<1,(($U4/$L4)*((1+Inputs!$D$7)^AG$2)),((INT(AG$2/$L4)-INT((AG$2-1)/$L4))*$U4*((1+Inputs!$D$7)^AG$2))),(_xlfn.WEIBULL.DIST(AG$2,$M4,$L4,FALSE)*$U4*((1+Inputs!$D$7)^AG$2))),IF($N4=Lists!$K$3,IF($L4<1,((($T4*(1-$F4)+$S4*(1-$G4))/$L4)*((1+Inputs!$D$7)^AG$2)),((INT(AG$2/$L4)-INT((AG$2-1)/$L4))*($T4*(1-$F4)+$S4*(1-$G4))*((1+Inputs!$D$7)^AG$2))),((_xlfn.WEIBULL.DIST(AG$2,$M4,$L4,FALSE)*($T4*(1-$F4)+$S4*(1-$G4))*((1+Inputs!$D$7)^AG$2)))))) -> 52.829379 | AH4: =$E4*IF(AH$2>Inputs!$D$5,0,IF(AH$2>VLOOKUP($H4,Lists!$P$3:$Q$7,2),IF($N4=Lists!$K$3,IF($L4<1,(($U4/$L4)*((1+Inputs!$D$7)^AH$2)),((INT(AH$2/$L4)-INT((AH$2-1)/$L4))*$U4*((1+Inputs!$D$7)^AH$2))),(_xlfn.WEIBULL.DIST(AH$2,$M4,$L4,FALSE)*$U4*((1+Inputs!$D$7)^AH$2))),IF($N4=Lists!$K$3,IF($L4<1,((($T4*(1-$F4)+$S4*(1-$G4))/$L4)*((1+Inputs!$D$7)^AH$2)),((INT(AH$2/$L4)-INT((AH$2-1)/$L4))*($T4*(1-$F4)+$S4*(1-$G4))*((1+Inputs!$D$7)^AH$2))),((_xlfn.WEIBULL.DIST(AH$2,$M4,$L4,FALSE)*($T4*(1-$F4)+$S4*(1-$G4))*((1+Inputs!$D$7)^AH$2)))))) -> 53.885967 | ... BN4: =$E4*IF(BN$2>Inputs!$D$5,0,IF(BN$2>VLOOKUP($H4,Lists!$P$3:$Q$7,2),IF($N4=Lists!$K$3,IF($L4<1,(($U4/$L4)*((1+Inputs!$D$7)^BN$2)),((INT(BN$2/$L4)-INT((BN$2-1)/$L4))*$U4*((1+Inputs!$D$7)^BN$2))),(_xlfn.WEIBULL.DIST(BN$2,$M4,$L4,FALSE)*$U4*((1+Inputs!$D$7)^BN$2))),IF($N4=Lists!$K$3,IF($L4<1,((($T4*(1-$F4)+$S4*(1-$G4))/$L4)*((1+Inputs!$D$7)^BN$2)),((INT(BN$2/$L4)-INT((BN$2-1)/$L4))*($T4*(1-$F4)+$S4*(1-$G4))*((1+Inputs!$D$7)^BN$2))),((_xlfn.WEIBULL.DIST(BN$2,$M4,$L4,FALSE)*($T4*(1-$F4)+$S4*(1-$G4))*((1+Inputs!$D$7)^BN$2)))))) -> 0 | BO4: =NPV(Inputs!$D$6,BQ4:DD4) -> 654.61425 | BP4: =BO4/SUM($Y$3:$Y$136) -> 0.00030874804 | BQ4: =MAX(AA4,($E4*IF(BQ$2>Inputs!$D$5,0,IF(BQ$2>VLOOKUP($H4,Lists!$P$3:$Q$7,2),IF($N4=Lists!$K$3,IF($L4<1,(($U4/$L4)*((1+Inputs!$D$7)^BQ$2)),((INT(BQ$2/$L4)-INT((BQ$2-1)/$L4))*$U4*((1+Inputs!$D$7)^BQ$2))),(Inputs!$D$8^((1-_xlfn.WEIBULL.DIST(BQ$2,$M4,$L4,FALSE))/_xlfn.WEIBULL.DIST(BQ$2,$M4,$L4,FALSE))*$U4*((1+Inputs!$D$7)^BQ$2))),IF($N4=Lists!$K$3,IF($L4<1,((($T4*(1-$F4)+$S4*(1-$G4))/$L4)*((1+Inputs!$D$7)^BQ$2)),((INT(BQ$2/$L4)-INT((BQ$2-1)/$L4))*($T4*(1-$F4)+$S4*(1-$G4))*((1+Inputs!$D$7)^BQ$2))),((Inputs!$D$8^((1-_xlfn.WEIBULL.DIST(BQ$2,$M4,$L4,FALSE))/_xlfn.WEIBULL.DIST(BQ$2,$M4,$L4,FALSE))*($T4*(1-$F4)+$S4*(1-$G4))*((1+Inputs!$D$7)^BQ$2)))))))) -> 46.910977 | BR4: =MAX(AB4,($E4*IF(BR$2>Inputs!$D$5,0,IF(BR$2>VLOOKUP($H4,Lists!$P$3:$Q$7,2),IF($N4=Lists!$K$3,IF($L4<1,(($U4/$L4)*((1+Inputs!$D$7)^BR$2)),((INT(BR$2/$L4)-INT((BR$2-1)/$L4))*$U4*((1+Inputs!$D$7)^BR$2))),(Inputs!$D$8^((1-_xlfn.WEIBULL.DIST(BR$2,$M4,$L4,FALSE))/_xlfn.WEIBULL.DIST(BR$2,$M4,$L4,FALSE))*$U4*((1+Inputs!$D$7)^BR$2))),IF($N4=Lists!$K$3,IF($L4<1,((($T4*(1-$F4)+$S4*(1-$G4))/$L4)*((1+Inputs!$D$7)^BR$2)),((INT(BR$2/$L4)-INT((BR$2-1)/$L4))*($T4*(1-$F4)+$S4*(1-$G4))*((1+Inputs!$D$7)^BR$2))),((Inputs!$D$8^((1-_xlfn.WEIBULL.DIST(BR$2,$M4,$L4,FALSE))/_xlfn.WEIBULL.DIST(BR$2,$M4,$L4,FALSE))*($T4*(1-$F4)+$S4*(1-$G4))*((1+Inputs!$D$7)^BR$2)))))))) -> 47.849196 | BS4: =MAX(AC4,($E4*IF(BS$2>Inputs!$D$5,0,IF(BS$2>VLOOKUP($H4,Lists!$P$3:$Q$7,2),IF($N4=Lists!$K$3,IF($L4<1,(($U4/$L4)*((1+Inputs!$D$7)^BS$2)),((INT(BS$2/$L4)-INT((BS$2-1)/$L4))*$U4*((1+Inputs!$D$7)^BS$2))),(Inputs!$D$8^((1-_xlfn.WEIBULL.DIST(BS$2,$M4,$L4,FALSE))/_xlfn.WEIBULL.DIST(BS$2,$M4,$L4,FALSE))*$U4*((1+Inputs!$D$7)^BS$2))),IF($N4=Lists!$K$3,IF($L4<1,((($T4*(1-$F4)+$S4*(1-$G4))/$L4)*((1+Inputs!$D$7)^BS$2)),((INT(BS$2/$L4)-INT((BS$2-1)/$L4))*($T4*(1-$F4)+$S4*(1-$G4))*((1+Inputs!$D$7)^BS$2))),((Inputs!$D$8^((1-_xlfn.WEIBULL.DIST(BS$2,$M4,$L4,FALSE))/_xlfn.WEIBULL.DIST(BS$2,$M4,$L4,FALSE))*($T4*(1-$F4)+$S4*(1-$G4))*((1+Inputs!$D$7)^BS$2)))))))) -> 48.80618 | BT4: =MAX(AD4,($E4*IF(BT$2>Inputs!$D$5,0,IF(BT$2>VLOOKUP($H4,Lists!$P$3:$Q$7,2),IF($N4=Lists!$K$3,IF($L4<1,(($U4/$L4)*((1+Inputs!$D$7)^BT$2)),((INT(BT$2/$L4)-INT((BT$2-1)/$L4))*$U4*((1+Inputs!$D$7)^BT$2))),(Inputs!$D$8^((1-_xlfn.WEIBULL.DIST(BT$2,$M4,$L4,FALSE))/_xlfn.WEIBULL.DIST(BT$2,$M4,$L4,FALSE))*$U4*((1+Inputs!$D$7)^BT$2))),IF($N4=Lists!$K$3,IF($L4<1,((($T4*(1-$F4)+$S4*(1-$G4))/$L4)*((1+Inputs!$D$7)^BT$2)),((INT(BT$2/$L4)-INT((BT$2-1)/$L4))*($T4*(1-$F4)+$S4*(1-$G4))*((1+Inputs!$D$7)^BT$2))),((Inputs!$D$8^((1-_xlfn.WEIBULL.DIST(BT$2,$M4,$L4,FALSE))/_xlfn.WEIBULL.DIST(BT$2,$M4,$L4,FALSE))*($T4*(1-$F4)+$S4*(1-$G4))*((1+Inputs!$D$7)^BT$2)))))))) -> 49.782304 | BU4: =MAX(AE4,($E4*IF(BU$2>Inputs!$D$5,0,IF(BU$2>VLOOKUP($H4,Lists!$P$3:$Q$7,2),IF($N4=Lists!$K$3,IF($L4<1,(($U4/$L4)*((1+Inputs!$D$7)^BU$2)),((INT(BU$2/$L4)-INT((BU$2-1)/$L4))*$U4*((1+Inputs!$D$7)^BU$2))),(Inputs!$D$8^((1-_xlfn.WEIBULL.DIST(BU$2,$M4,$L4,FALSE))/_xlfn.WEIBULL.DIST(BU$2,$M4,$L4,FALSE))*$U4*((1+Inputs!$D$7)^BU$2))),IF($N4=Lists!$K$3,IF($L4<1,((($T4*(1-$F4)+$S4*(1-$G4))/$L4)*((1+Inputs!$D$7)^BU$2)),((INT(BU$2/$L4)-INT((BU$2-1)/$L4))*($T4*(1-$F4)+$S4*(1-$G4))*((1+Inputs!$D$7)^BU$2))),((Inputs!$D$8^((1-_xlfn.WEIBULL.DIST(BU$2,$M4,$L4,FALSE))/_xlfn.WEIBULL.DIST(BU$2,$M4,$L4,FALSE))*($T4*(1-$F4)+$S4*(1-$G4))*((1+Inputs!$D$7)^BU$2)))))))) -> 50.77795 | BV4: =MAX(AF4,($E4*IF(BV$2>Inputs!$D$5,0,IF(BV$2>VLOOKUP($H4,Lists!$P$3:$Q$7,2),IF($N4=Lists!$K$3,IF($L4<1,(($U4/$L4)*((1+Inputs!$D$7)^BV$2)),((INT(BV$2/$L4)-INT((BV$2-1)/$L4))*$U4*((1+Inputs!$D$7)^BV$2))),(Inputs!$D$8^((1-_xlfn.WEIBULL.DIST(BV$2,$M4,$L4,FALSE))/_xlfn.WEIBULL.DIST(BV$2,$M4,$L4,FALSE))*$U4*((1+Inputs!$D$7)^BV$2))),IF($N4=Lists!$K$3,IF($L4<1,((($T4*(1-$F4)+$S4*(1-$G4))/$L4)*((1+Inputs!$D$7)^BV$2)),((INT(BV$2/$L4)-INT((BV$2-1)/$L4))*($T4*(1-$F4)+$S4*(1-$G4))*((1+Inputs!$D$7)^BV$2))),((Inputs!$D$8^((1-_xlfn.WEIBULL.DIST(BV$2,$M4,$L4,FALSE))/_xlfn.WEIBULL.DIST(BV$2,$M4,$L4,FALSE))*($T4*(1-$F4)+$S4*(1-$G4))*((1+Inputs!$D$7)^BV$2)))))))) -> 51.793509 | BW4: =MAX(AG4,($E4*IF(BW$2>Inputs!$D$5,0,IF(BW$2>VLOOKUP($H4,Lists!$P$3:$Q$7,2),IF($N4=Lists!$K$3,IF($L4<1,(($U4/$L4)*((1+Inputs!$D$7)^BW$2)),((INT(BW$2/$L4)-INT((BW$2-1)/$L4))*$U4*((1+Inputs!$D$7)^BW$2))),(Inputs!$D$8^((1-_xlfn.WEIBULL.DIST(BW$2,$M4,$L4,FALSE))/_xlfn.WEIBULL.DIST(BW$2,$M4,$L4,FALSE))*$U4*((1+Inputs!$D$7)^BW$2))),IF($N4=Lists!$K$3,IF($L4<1,((($T4*(1-$F4)+$S4*(1-$G4))/$L4)*((1+Inputs!$D$7)^BW$2)),((INT(BW$2/$L4)-INT((BW$2-1)/$L4))*($T4*(1-$F4)+$S4*(1-$G4))*((1+Inputs!$D$7)^BW$2))),((Inputs!$D$8^((1-_xlfn.WEIBULL.DIST(BW$2,$M4,$L4,FALSE))/_xlfn.WEIBULL.DIST(BW$2,$M4,$L4,FALSE))*($T4*(1-$F4)+$S4*(1-$G4))*((1+Inputs!$D$7)^BW$2)))))))) -> 52.829379 | BX4: =MAX(AH4,($E4*IF(BX$2>Inputs!$D$5,0,IF(BX$2>VLOOKUP($H4,Lists!$P$3:$Q$7,2),IF($N4=Lists!$K$3,IF($L4<1,(($U4/$L4)*((1+Inputs!$D$7)^BX$2)),((INT(BX$2/$L4)-INT((BX$2-1)/$L4))*$U4*((1+Inputs!$D$7)^BX$2))),(Inputs!$D$8^((1-_xlfn.WEIBULL.DIST(BX$2,$M4,$L4,FALSE))/_xlfn.WEIBULL.DIST(BX$2,$M4,$L4,FALSE))*$U4*((1+Inputs!$D$7)^BX$2))),IF($N4=Lists!$K$3,IF($L4<1,((($T4*(1-$F4)+$S4*(1-$G4))/$L4)*((1+Inputs!$D$7)^BX$2)),((INT(BX$2/$L4)-INT((BX$2-1)/$L4))*($T4*(1-$F4)+$S4*(1-$G4))*((1+Inputs!$D$7)^BX$2))),((Inputs!$D$8^((1-_xlfn.WEIBULL.DIST(BX$2,$M4,$L4,FALSE))/_xlfn.WEIBULL.DIST(BX$2,$M4,$L4,FALSE))*($T4*(1-$F4)+$S4*(1-$G4))*((1+Inputs!$D$7)^BX$2)))))))) -> 53.885967 | ... DD4: =MAX(BN4,($E4*IF(DD$2>Inputs!$D$5,0,IF(DD$2>VLOOKUP($H4,Lists!$P$3:$Q$7,2),IF($N4=Lists!$K$3,IF($L4<1,(($U4/$L4)*((1+Inputs!$D$7)^DD$2)),((INT(DD$2/$L4)-INT((DD$2-1)/$L4))*$U4*((1+Inputs!$D$7)^DD$2))),(Inputs!$D$8^((1-_xlfn.WEIBULL.DIST(DD$2,$M4,$L4,FALSE))/_xlfn.WEIBULL.DIST(DD$2,$M4,$L4,FALSE))*$U4*((1+Inputs!$D$7)^DD$2))),IF($N4=Lists!$K$3,IF($L4<1,((($T4*(1-$F4)+$S4*(1-$G4))/$L4)*((1+Inputs!$D$7)^DD$2)),((INT(DD$2/$L4)-INT((DD$2-1)/$L4))*($T4*(1-$F4)+$S4*(1-$G4))*((1+Inputs!$D$7)^DD$2))),((Inputs!$D$8^((1-_xlfn.WEIBULL.DIST(DD$2,$M4,$L4,FALSE))/_xlfn.WEIBULL.DIST(DD$2,$M4,$L4,FALSE))*($T4*(1-$F4)+$S4*(1-$G4))*((1+Inputs!$D$7)^DD$2)))))))) -> 0
A5: Meet with key site staff to continue awareness, question any issues, and report on findings. | B5: Administration | C5: Management | D5: Documents | E5: =IF(Inputs!D41=Lists!I4,0,1) -> 1 | F5: 0 | G5: 0 | H5: N/A | J5: Administrator | K5: =VLOOKUP(J5,'Labor Rates'!$A$1:$F$16,2) -> 22.995577 | L5: 1 | M5: 1 | N5: interval | O5: 1 | P5: 2 | Q5: =O5*P5/L5 -> 2 | R5: 0 | S5: =P5*O5*K5 -> 45.991154 | T5: =R5*O5 -> 0 | U5: =E5*(T5+S5) -> 45.991154 | X5: =AVERAGE(AA5:AT5) -> 56.990668 | Y5: =NPV(Inputs!$D$6,AA5:BN5) -> 654.61425 | Z5: =Y5/SUM($Y$3:$Y$136) -> 0.00030874804 | AA5: =$E5*IF(AA$2>Inputs!$D$5,0,IF(AA$2>VLOOKUP($H5,Lists!$P$3:$Q$7,2),IF($N5=Lists!$K$3,IF($L5<1,(($U5/$L5)*((1+Inputs!$D$7)^AA$2)),((INT(AA$2/$L5)-INT((AA$2-1)/$L5))*$U5*((1+Inputs!$D$7)^AA$2))),(_xlfn.WEIBULL.DIST(AA$2,$M5,$L5,FALSE)*$U5*((1+Inputs!$D$7)^AA$2))),IF($N5=Lists!$K$3,IF($L5<1,((($T5*(1-$F5)+$S5*(1-$G5))/$L5)*((1+Inputs!$D$7)^AA$2)),((INT(AA$2/$L5)-INT((AA$2-1)/$L5))*($T5*(1-$F5)+$S5*(1-$G5))*((1+Inputs!$D$7)^AA$2))),((_xlfn.WEIBULL.DIST(AA$2,$M5,$L5,FALSE)*($T5*(1-$F5)+$S5*(1-$G5))*((1+Inputs!$D$7)^AA$2)))))) -> 46.910977 | AB5: =$E5*IF(AB$2>Inputs!$D$5,0,IF(AB$2>VLOOKUP($H5,Lists!$P$3:$Q$7,2),IF($N5=Lists!$K$3,IF($L5<1,(($U5/$L5)*((1+Inputs!$D$7)^AB$2)),((INT(AB$2/$L5)-INT((AB$2-1)/$L5))*$U5*((1+Inputs!$D$7)^AB$2))),(_xlfn.WEIBULL.DIST(AB$2,$M5,$L5,FALSE)*$U5*((1+Inputs!$D$7)^AB$2))),IF($N5=Lists!$K$3,IF($L5<1,((($T5*(1-$F5)+$S5*(1-$G5))/$L5)*((1+Inputs!$D$7)^AB$2)),((INT(AB$2/$L5)-INT((AB$2-1)/$L5))*($T5*(1-$F5)+$S5*(1-$G5))*((1+Inputs!$D$7)^AB$2))),((_xlfn.WEIBULL.DIST(AB$2,$M5,$L5,FALSE)*($T5*(1-$F5)+$S5*(1-$G5))*((1+Inputs!$D$7)^AB$2)))))) -> 47.849196 | AC5: =$E5*IF(AC$2>Inputs!$D$5,0,IF(AC$2>VLOOKUP($H5,Lists!$P$3:$Q$7,2),IF($N5=Lists!$K$3,IF($L5<1,(($U5/$L5)*((1+Inputs!$D$7)^AC$2)),((INT(AC$2/$L5)-INT((AC$2-1)/$L5))*$U5*((1+Inputs!$D$7)^AC$2))),(_xlfn.WEIBULL.DIST(AC$2,$M5,$L5,FALSE)*$U5*((1+Inputs!$D$7)^AC$2))),IF($N5=Lists!$K$3,IF($L5<1,((($T5*(1-$F5)+$S5*(1-$G5))/$L5)*((1+Inputs!$D$7)^AC$2)),((INT(AC$2/$L5)-INT((AC$2-1)/$L5))*($T5*(1-$F5)+$S5*(1-$G5))*((1+Inputs!$D$7)^AC$2))),((_xlfn.WEIBULL.DIST(AC$2,$M5,$L5,FALSE)*($T5*(1-$F5)+$S5*(1-$G5))*((1+Inputs!$D$7)^AC$2)))))) -> 48.80618 | AD5: =$E5*IF(AD$2>Inputs!$D$5,0,IF(AD$2>VLOOKUP($H5,Lists!$P$3:$Q$7,2),IF($N5=Lists!$K$3,IF($L5<1,(($U5/$L5)*((1+Inputs!$D$7)^AD$2)),((INT(AD$2/$L5)-INT((AD$2-1)/$L5))*$U5*((1+Inputs!$D$7)^AD$2))),(_xlfn.WEIBULL.DIST(AD$2,$M5,$L5,FALSE)*$U5*((1+Inputs!$D$7)^AD$2))),IF($N5=Lists!$K$3,IF($L5<1,((($T5*(1-$F5)+$S5*(1-$G5))/$L5)*((1+Inputs!$D$7)^AD$2)),((INT(AD$2/$L5)-INT((AD$2-1)/$L5))*($T5*(1-$F5)+$S5*(1-$G5))*((1+Inputs!$D$7)^AD$2))),((_xlfn.WEIBULL.DIST(AD$2,$M5,$L5,FALSE)*($T5*(1-$F5)+$S5*(1-$G5))*((1+Inputs!$D$7)^AD$2)))))) -> 49.782304 | AE5: =$E5*IF(AE$2>Inputs!$D$5,0,IF(AE$2>VLOOKUP($H5,Lists!$P$3:$Q$7,2),IF($N5=Lists!$K$3,IF($L5<1,(($U5/$L5)*((1+Inputs!$D$7)^AE$2)),((INT(AE$2/$L5)-INT((AE$2-1)/$L5))*$U5*((1+Inputs!$D$7)^AE$2))),(_xlfn.WEIBULL.DIST(AE$2,$M5,$L5,FALSE)*$U5*((1+Inputs!$D$7)^AE$2))),IF($N5=Lists!$K$3,IF($L5<1,((($T5*(1-$F5)+$S5*(1-$G5))/$L5)*((1+Inputs!$D$7)^AE$2)),((INT(AE$2/$L5)-INT((AE$2-1)/$L5))*($T5*(1-$F5)+$S5*(1-$G5))*((1+Inputs!$D$7)^AE$2))),((_xlfn.WEIBULL.DIST(AE$2,$M5,$L5,FALSE)*($T5*(1-$F5)+$S5*(1-$G5))*((1+Inputs!$D$7)^AE$2)))))) -> 50.77795 | AF5: =$E5*IF(AF$2>Inputs!$D$5,0,IF(AF$2>VLOOKUP($H5,Lists!$P$3:$Q$7,2),IF($N5=Lists!$K$3,IF($L5<1,(($U5/$L5)*((1+Inputs!$D$7)^AF$2)),((INT(AF$2/$L5)-INT((AF$2-1)/$L5))*$U5*((1+Inputs!$D$7)^AF$2))),(_xlfn.WEIBULL.DIST(AF$2,$M5,$L5,FALSE)*$U5*((1+Inputs!$D$7)^AF$2))),IF($N5=Lists!$K$3,IF($L5<1,((($T5*(1-$F5)+$S5*(1-$G5))/$L5)*((1+Inputs!$D$7)^AF$2)),((INT(AF$2/$L5)-INT((AF$2-1)/$L5))*($T5*(1-$F5)+$S5*(1-$G5))*((1+Inputs!$D$7)^AF$2))),((_xlfn.WEIBULL.DIST(AF$2,$M5,$L5,FALSE)*($T5*(1-$F5)+$S5*(1-$G5))*((1+Inputs!$D$7)^AF$2)))))) -> 51.793509 | AG5: =$E5*IF(AG$2>Inputs!$D$5,0,IF(AG$2>VLOOKUP($H5,Lists!$P$3:$Q$7,2),IF($N5=Lists!$K$3,IF($L5<1,(($U5/$L5)*((1+Inputs!$D$7)^AG$2)),((INT(AG$2/$L5)-INT((AG$2-1)/$L5))*$U5*((1+Inputs!$D$7)^AG$2))),(_xlfn.WEIBULL.DIST(AG$2,$M5,$L5,FALSE)*$U5*((1+Inputs!$D$7)^AG$2))),IF($N5=Lists!$K$3,IF($L5<1,((($T5*(1-$F5)+$S5*(1-$G5))/$L5)*((1+Inputs!$D$7)^AG$2)),((INT(AG$2/$L5)-INT((AG$2-1)/$L5))*($T5*(1-$F5)+$S5*(1-$G5))*((1+Inputs!$D$7)^AG$2))),((_xlfn.WEIBULL.DIST(AG$2,$M5,$L5,FALSE)*($T5*(1-$F5)+$S5*(1-$G5))*((1+Inputs!$D$7)^AG$2)))))) -> 52.829379 | AH5: =$E5*IF(AH$2>Inputs!$D$5,0,IF(AH$2>VLOOKUP($H5,Lists!$P$3:$Q$7,2),IF($N5=Lists!$K$3,IF($L5<1,(($U5/$L5)*((1+Inputs!$D$7)^AH$2)),((INT(AH$2/$L5)-INT((AH$2-1)/$L5))*$U5*((1+Inputs!$D$7)^AH$2))),(_xlfn.WEIBULL.DIST(AH$2,$M5,$L5,FALSE)*$U5*((1+Inputs!$D$7)^AH$2))),IF($N5=Lists!$K$3,IF($L5<1,((($T5*(1-$F5)+$S5*(1-$G5))/$L5)*((1+Inputs!$D$7)^AH$2)),((INT(AH$2/$L5)-INT((AH$2-1)/$L5))*($T5*(1-$F5)+$S5*(1-$G5))*((1+Inputs!$D$7)^AH$2))),((_xlfn.WEIBULL.DIST(AH$2,$M5,$L5,FALSE)*($T5*(1-$F5)+$S5*(1-$G5))*((1+Inputs!$D$7)^AH$2)))))) -> 53.885967 | ... BN5: =$E5*IF(BN$2>Inputs!$D$5,0,IF(BN$2>VLOOKUP($H5,Lists!$P$3:$Q$7,2),IF($N5=Lists!$K$3,IF($L5<1,(($U5/$L5)*((1+Inputs!$D$7)^BN$2)),((INT(BN$2/$L5)-INT((BN$2-1)/$L5))*$U5*((1+Inputs!$D$7)^BN$2))),(_xlfn.WEIBULL.DIST(BN$2,$M5,$L5,FALSE)*$U5*((1+Inputs!$D$7)^BN$2))),IF($N5=Lists!$K$3,IF($L5<1,((($T5*(1-$F5)+$S5*(1-$G5))/$L5)*((1+Inputs!$D$7)^BN$2)),((INT(BN$2/$L5)-INT((BN$2-1)/$L5))*($T5*(1-$F5)+$S5*(1-$G5))*((1+Inputs!$D$7)^BN$2))),((_xlfn.WEIBULL.DIST(BN$2,$M5,$L5,FALSE)*($T5*(1-$F5)+$S5*(1-$G5))*((1+Inputs!$D$7)^BN$2)))))) -> 0 | BO5: =NPV(Inputs!$D$6,BQ5:DD5) -> 654.61425 | BP5: =BO5/SUM($Y$3:$Y$136) -> 0.00030874804 | BQ5: =MAX(AA5,($E5*IF(BQ$2>Inputs!$D$5,0,IF(BQ$2>VLOOKUP($H5,Lists!$P$3:$Q$7,2),IF($N5=Lists!$K$3,IF($L5<1,(($U5/$L5)*((1+Inputs!$D$7)^BQ$2)),((INT(BQ$2/$L5)-INT((BQ$2-1)/$L5))*$U5*((1+Inputs!$D$7)^BQ$2))),(Inputs!$D$8^((1-_xlfn.WEIBULL.DIST(BQ$2,$M5,$L5,FALSE))/_xlfn.WEIBULL.DIST(BQ$2,$M5,$L5,FALSE))*$U5*((1+Inputs!$D$7)^BQ$2))),IF($N5=Lists!$K$3,IF($L5<1,((($T5*(1-$F5)+$S5*(1-$G5))/$L5)*((1+Inputs!$D$7)^BQ$2)),((INT(BQ$2/$L5)-INT((BQ$2-1)/$L5))*($T5*(1-$F5)+$S5*(1-$G5))*((1+Inputs!$D$7)^BQ$2))),((Inputs!$D$8^((1-_xlfn.WEIBULL.DIST(BQ$2,$M5,$L5,FALSE))/_xlfn.WEIBULL.DIST(BQ$2,$M5,$L5,FALSE))*($T5*(1-$F5)+$S5*(1-$G5))*((1+Inputs!$D$7)^BQ$2)))))))) -> 46.910977 | BR5: =MAX(AB5,($E5*IF(BR$2>Inputs!$D$5,0,IF(BR$2>VLOOKUP($H5,Lists!$P$3:$Q$7,2),IF($N5=Lists!$K$3,IF($L5<1,(($U5/$L5)*((1+Inputs!$D$7)^BR$2)),((INT(BR$2/$L5)-INT((BR$2-1)/$L5))*$U5*((1+Inputs!$D$7)^BR$2))),(Inputs!$D$8^((1-_xlfn.WEIBULL.DIST(BR$2,$M5,$L5,FALSE))/_xlfn.WEIBULL.DIST(BR$2,$M5,$L5,FALSE))*$U5*((1+Inputs!$D$7)^BR$2))),IF($N5=Lists!$K$3,IF($L5<1,((($T5*(1-$F5)+$S5*(1-$G5))/$L5)*((1+Inputs!$D$7)^BR$2)),((INT(BR$2/$L5)-INT((BR$2-1)/$L5))*($T5*(1-$F5)+$S5*(1-$G5))*((1+Inputs!$D$7)^BR$2))),((Inputs!$D$8^((1-_xlfn.WEIBULL.DIST(BR$2,$M5,$L5,FALSE))/_xlfn.WEIBULL.DIST(BR$2,$M5,$L5,FALSE))*($T5*(1-$F5)+$S5*(1-$G5))*((1+Inputs!$D$7)^BR$2)))))))) -> 47.849196 | BS5: =MAX(AC5,($E5*IF(BS$2>Inputs!$D$5,0,IF(BS$2>VLOOKUP($H5,Lists!$P$3:$Q$7,2),IF($N5=Lists!$K$3,IF($L5<1,(($U5/$L5)*((1+Inputs!$D$7)^BS$2)),((INT(BS$2/$L5)-INT((BS$2-1)/$L5))*$U5*((1+Inputs!$D$7)^BS$2))),(Inputs!$D$8^((1-_xlfn.WEIBULL.DIST(BS$2,$M5,$L5,FALSE))/_xlfn.WEIBULL.DIST(BS$2,$M5,$L5,FALSE))*$U5*((1+Inputs!$D$7)^BS$2))),IF($N5=Lists!$K$3,IF($L5<1,((($T5*(1-$F5)+$S5*(1-$G5))/$L5)*((1+Inputs!$D$7)^BS$2)),((INT(BS$2/$L5)-INT((BS$2-1)/$L5))*($T5*(1-$F5)+$S5*(1-$G5))*((1+Inputs!$D$7)^BS$2))),((Inputs!$D$8^((1-_xlfn.WEIBULL.DIST(BS$2,$M5,$L5,FALSE))/_xlfn.WEIBULL.DIST(BS$2,$M5,$L5,FALSE))*($T5*(1-$F5)+$S5*(1-$G5))*((1+Inputs!$D$7)^BS$2)))))))) -> 48.80618 | BT5: =MAX(AD5,($E5*IF(BT$2>Inputs!$D$5,0,IF(BT$2>VLOOKUP($H5,Lists!$P$3:$Q$7,2),IF($N5=Lists!$K$3,IF($L5<1,(($U5/$L5)*((1+Inputs!$D$7)^BT$2)),((INT(BT$2/$L5)-INT((BT$2-1)/$L5))*$U5*((1+Inputs!$D$7)^BT$2))),(Inputs!$D$8^((1-_xlfn.WEIBULL.DIST(BT$2,$M5,$L5,FALSE))/_xlfn.WEIBULL.DIST(BT$2,$M5,$L5,FALSE))*$U5*((1+Inputs!$D$7)^BT$2))),IF($N5=Lists!$K$3,IF($L5<1,((($T5*(1-$F5)+$S5*(1-$G5))/$L5)*((1+Inputs!$D$7)^BT$2)),((INT(BT$2/$L5)-INT((BT$2-1)/$L5))*($T5*(1-$F5)+$S5*(1-$G5))*((1+Inputs!$D$7)^BT$2))),((Inputs!$D$8^((1-_xlfn.WEIBULL.DIST(BT$2,$M5,$L5,FALSE))/_xlfn.WEIBULL.DIST(BT$2,$M5,$L5,FALSE))*($T5*(1-$F5)+$S5*(1-$G5))*((1+Inputs!$D$7)^BT$2)))))))) -> 49.782304 | BU5: =MAX(AE5,($E5*IF(BU$2>Inputs!$D$5,0,IF(BU$2>VLOOKUP($H5,Lists!$P$3:$Q$7,2),IF($N5=Lists!$K$3,IF($L5<1,(($U5/$L5)*((1+Inputs!$D$7)^BU$2)),((INT(BU$2/$L5)-INT((BU$2-1)/$L5))*$U5*((1+Inputs!$D$7)^BU$2))),(Inputs!$D$8^((1-_xlfn.WEIBULL.DIST(BU$2,$M5,$L5,FALSE))/_xlfn.WEIBULL.DIST(BU$2,$M5,$L5,FALSE))*$U5*((1+Inputs!$D$7)^BU$2))),IF($N5=Lists!$K$3,IF($L5<1,((($T5*(1-$F5)+$S5*(1-$G5))/$L5)*((1+Inputs!$D$7)^BU$2)),((INT(BU$2/$L5)-INT((BU$2-1)/$L5))*($T5*(1-$F5)+$S5*(1-$G5))*((1+Inputs!$D$7)^BU$2))),((Inputs!$D$8^((1-_xlfn.WEIBULL.DIST(BU$2,$M5,$L5,FALSE))/_xlfn.WEIBULL.DIST(BU$2,$M5,$L5,FALSE))*($T5*(1-$F5)+$S5*(1-$G5))*((1+Inputs!$D$7)^BU$2)))))))) -> 50.77795 | BV5: =MAX(AF5,($E5*IF(BV$2>Inputs!$D$5,0,IF(BV$2>VLOOKUP($H5,Lists!$P$3:$Q$7,2),IF($N5=Lists!$K$3,IF($L5<1,(($U5/$L5)*((1+Inputs!$D$7)^BV$2)),((INT(BV$2/$L5)-INT((BV$2-1)/$L5))*$U5*((1+Inputs!$D$7)^BV$2))),(Inputs!$D$8^((1-_xlfn.WEIBULL.DIST(BV$2,$M5,$L5,FALSE))/_xlfn.WEIBULL.DIST(BV$2,$M5,$L5,FALSE))*$U5*((1+Inputs!$D$7)^BV$2))),IF($N5=Lists!$K$3,IF($L5<1,((($T5*(1-$F5)+$S5*(1-$G5))/$L5)*((1+Inputs!$D$7)^BV$2)),((INT(BV$2/$L5)-INT((BV$2-1)/$L5))*($T5*(1-$F5)+$S5*(1-$G5))*((1+Inputs!$D$7)^BV$2))),((Inputs!$D$8^((1-_xlfn.WEIBULL.DIST(BV$2,$M5,$L5,FALSE))/_xlfn.WEIBULL.DIST(BV$2,$M5,$L5,FALSE))*($T5*(1-$F5)+$S5*(1-$G5))*((1+Inputs!$D$7)^BV$2)))))))) -> 51.793509 | BW5: =MAX(AG5,($E5*IF(BW$2>Inputs!$D$5,0,IF(BW$2>VLOOKUP($H5,Lists!$P$3:$Q$7,2),IF($N5=Lists!$K$3,IF($L5<1,(($U5/$L5)*((1+Inputs!$D$7)^BW$2)),((INT(BW$2/$L5)-INT((BW$2-1)/$L5))*$U5*((1+Inputs!$D$7)^BW$2))),(Inputs!$D$8^((1-_xlfn.WEIBULL.DIST(BW$2,$M5,$L5,FALSE))/_xlfn.WEIBULL.DIST(BW$2,$M5,$L5,FALSE))*$U5*((1+Inputs!$D$7)^BW$2))),IF($N5=Lists!$K$3,IF($L5<1,((($T5*(1-$F5)+$S5*(1-$G5))/$L5)*((1+Inputs!$D$7)^BW$2)),((INT(BW$2/$L5)-INT((BW$2-1)/$L5))*($T5*(1-$F5)+$S5*(1-$G5))*((1+Inputs!$D$7)^BW$2))),((Inputs!$D$8^((1-_xlfn.WEIBULL.DIST(BW$2,$M5,$L5,FALSE))/_xlfn.WEIBULL.DIST(BW$2,$M5,$L5,FALSE))*($T5*(1-$F5)+$S5*(1-$G5))*((1+Inputs!$D$7)^BW$2)))))))) -> 52.829379 | BX5: =MAX(AH5,($E5*IF(BX$2>Inputs!$D$5,0,IF(BX$2>VLOOKUP($H5,Lists!$P$3:$Q$7,2),IF($N5=Lists!$K$3,IF($L5<1,(($U5/$L5)*((1+Inputs!$D$7)^BX$2)),((INT(BX$2/$L5)-INT((BX$2-1)/$L5))*$U5*((1+Inputs!$D$7)^BX$2))),(Inputs!$D$8^((1-_xlfn.WEIBULL.DIST(BX$2,$M5,$L5,FALSE))/_xlfn.WEIBULL.DIST(BX$2,$M5,$L5,FALSE))*$U5*((1+Inputs!$D$7)^BX$2))),IF($N5=Lists!$K$3,IF($L5<1,((($T5*(1-$F5)+$S5*(1-$G5))/$L5)*((1+Inputs!$D$7)^BX$2)),((INT(BX$2/$L5)-INT((BX$2-1)/$L5))*($T5*(1-$F5)+$S5*(1-$G5))*((1+Inputs!$D$7)^BX$2))),((Inputs!$D$8^((1-_xlfn.WEIBULL.DIST(BX$2,$M5,$L5,FALSE))/_xlfn.WEIBULL.DIST(BX$2,$M5,$L5,FALSE))*($T5*(1-$F5)+$S5*(1-$G5))*((1+Inputs!$D$7)^BX$2)))))))) -> 53.885967 | ... DD5: =MAX(BN5,($E5*IF(DD$2>Inputs!$D$5,0,IF(DD$2>VLOOKUP($H5,Lists!$P$3:$Q$7,2),IF($N5=Lists!$K$3,IF($L5<1,(($U5/$L5)*((1+Inputs!$D$7)^DD$2)),((INT(DD$2/$L5)-INT((DD$2-1)/$L5))*$U5*((1+Inputs!$D$7)^DD$2))),(Inputs!$D$8^((1-_xlfn.WEIBULL.DIST(DD$2,$M5,$L5,FALSE))/_xlfn.WEIBULL.DIST(DD$2,$M5,$L5,FALSE))*$U5*((1+Inputs!$D$7)^DD$2))),IF($N5=Lists!$K$3,IF($L5<1,((($T5*(1-$F5)+$S5*(1-$G5))/$L5)*((1+Inputs!$D$7)^DD$2)),((INT(DD$2/$L5)-INT((DD$2-1)/$L5))*($T5*(1-$F5)+$S5*(1-$G5))*((1+Inputs!$D$7)^DD$2))),((Inputs!$D$8^((1-_xlfn.WEIBULL.DIST(DD$2,$M5,$L5,FALSE))/_xlfn.WEIBULL.DIST(DD$2,$M5,$L5,FALSE))*($T5*(1-$F5)+$S5*(1-$G5))*((1+Inputs!$D$7)^DD$2)))))))) -> 0
